<?xml version="1.0"?>
<robot xmlns:xacro="http://www.ros.org/wiki/xacro">

    <xacro:macro name="mobile_fr3_duo_v0_2"
        params="robot_types
                        hand
                        ros2_control
                        gazebo
                        gazebo_effort
                        use_fake_hardware
                        fake_sensor_commands
                        reduced_version
                        robot_ips
                        description_pkg
                        connected_to
                        use_arms
                        no_prefix
                        ee_id
                        special_connection
                        xyz_ee
                        rpy_ee
                        tcp_xyz
                        tcp_rpy
                        safety_distance
                        with_sc">
            
    <xacro:include filename="$(find franka_description)/robots/common/franka_robot.xacro"/>
    <xacro:include filename="$(find franka_description)/robots/fr3_duo/fr3_duo_mount/fr3_duo_mount.xacro" />
    <xacro:include filename="$(find franka_description)/robots/tmrv0_2/tmrv0_2.xacro"/>
    <xacro:include filename="$(find franka_description)/robots/mobile_fr3_duo_v0_2/mobile_fr3_duo.ros2_control.xacro"/>
    <xacro:include filename="$(find franka_description)/robots/fr3_duo/fr3_duo_head.xacro" />

    <xacro:if value="${gazebo}">
        <xacro:property name="ros_control_flag_for_real_hardware" value ="false"/>
    </xacro:if>
    <xacro:unless value="${gazebo}">
         <xacro:property name="ros_control_flag_for_real_hardware" value ="${ros2_control}"/>
    </xacro:unless>

    <xacro:property name="number_of_robots" value = "3"/>
    <xacro:property name="arm_prefixes_list" value="${['','left','right']}" /> 
    <xacro:macro name="loop" params="i">
        <xacro:unless value="${i == number_of_robots}">
        <xacro:property name="robot_type_i" value="${robot_types_list[i]}"/>
        <xacro:if value="${robot_type_i == 'tmrv0_2'}">
                <xacro:tmrv0_2 mobile_robot_type="${robot_type_i}"
                    robot_ip="${robot_ips_list[i]}"
                    ros2_control="${ros_control_flag_for_real_hardware}"
                    use_fake_hardware="${use_fake_hardware}"
                    fake_sensor_commands="${fake_sensor_commands}"
                    reduced_version="${reduced_version}"
                    gazebo="${gazebo}"/>

            <link name="franka_spine">
            <visual name="franka_spine_visual">
                <geometry>
                <mesh filename="package://franka_description/meshes/accessories/franka_spine/visual/franka_spine.dae" />
                </geometry>
            </visual>
            <collision name="franka_spine_collision">
                <geometry>
                <mesh filename="package://franka_description/meshes/accessories/franka_spine/collision/franka_spine.stl" />
                </geometry>
                <material name="red">
                <color rgba="1 0 0 1"/>
                </material>
            </collision>
            <inertial>
                <origin xyz="0.042358 0.000378 0.495198" rpy="0 0 0"/>
                <mass value="21.909124"/>
                <inertia
                ixx="3.338968145"
                ixy="-0.000642887"
                ixz="0.299962762"
                iyy="3.324560297"
                iyz="-0.004488422"
                izz="0.281489258"/>
            </inertial>
            </link>
            <joint name="franka_spine_fixed_joint" type="fixed">
            <parent link="base_link" />
            <child link="franka_spine" />
            <origin xyz="0.138289 0.0 0.350" rpy="0 0 0" />
            </joint>
            <link name="franka_spine_support">
            <inertial>
                <origin xyz="0 0 0" rpy="0 0 0"/>
                <mass value="0.01"/>
                <inertia ixx="0.0001" ixy="0.0" ixz="0.0"
                        iyy="0.0001" iyz="0.0" izz="0.0001"/>
            </inertial>
            </link>
            <joint name="franka_spine_vertical_joint" type="prismatic">
            <parent link="franka_spine" />
            <child link="franka_spine_support" />
            <origin xyz="0.266711 0.0 0.1" rpy="0 0 0" />
            <axis xyz="0 0 1"/>
            <limit effort="100" lower="0.0" upper="0.85" velocity="0.1" />
            </joint>

            <xacro:arg name="mount_kinematics" default="$(find franka_description)/robots/fr3_duo/fr3_duo_mount/kinematics.yaml"/>
            <xacro:mount name="mount" parent="franka_spine_support" inertials="${xacro.load_yaml('$(find franka_description)/robots/fr3_duo/fr3_duo_mount/inertials.yaml')}">
                <origin xyz="0 0 0" rpy="0 0 0" />
            </xacro:mount>

            <xacro:head name="head" parent="mount_link">
                <origin xyz="0 0 0.167" rpy="0 0 0" />
            </xacro:head>

        </xacro:if>
        <xacro:unless value="${robot_type_i == 'tmrv0_2'}">
            <xacro:if value="${use_arms}">
            <xacro:property name="mount_to_base" value="${xacro.load_yaml('$(arg mount_kinematics)')}"/>
            <xacro:property name="robot_prefix" value="${arm_prefixes_list[i]}"/>
            <xacro:property name="modified_prefix" value="${robot_prefix + '_' if robot_prefix else ''}"/>
            <joint name="${arm_prefixes_list[i]}_base_joint" type="fixed">
                <parent link="mount_link"/>
                <child link="${arm_prefixes_list[i]}_base"/>
                <xacro:if value="${robot_prefix == 'left'}">
                <xacro:property name="mount_corner" value="${mount_to_base['left']}" lazy_eval="false" />
                </xacro:if>
                <xacro:if value="${robot_prefix == 'right'}">
                <xacro:property name="mount_corner" value="${mount_to_base['right']}" lazy_eval="false" />
                </xacro:if>
                <origin rpy="${mount_corner.kinematic.roll} ${mount_corner.kinematic.pitch} ${mount_corner.kinematic.yaw}" xyz="${mount_corner.kinematic.x} ${mount_corner.kinematic.y} ${mount_corner.kinematic.z}"/>
            </joint>

            <xacro:arg name="inertials_path" default="$(find franka_description)/robots/${robot_type_i}/inertials.yaml"/>
            <xacro:arg name="kinematics_path" default="$(find franka_description)/robots/${robot_type_i}/kinematics.yaml"/>
            <xacro:arg name="dynamics_path" default="$(find franka_description)/robots/${robot_type_i}/dynamics.yaml"/>
            <xacro:arg name="joint_limits_path" default="$(find franka_description)/robots/${robot_type_i}/joint_limits.yaml"/>
            <xacro:arg name="accelerometers_path" default="$(find franka_description)/robots/${robot_type_i}/accelerometers.yaml"/>
            <xacro:franka_robot robot_type="${robot_type_i}"
                                joint_limits="${xacro.load_yaml('$(arg joint_limits_path)')}"
                                inertials="${xacro.load_yaml('$(arg inertials_path)')}"
                                kinematics="${xacro.load_yaml('$(arg kinematics_path)')}"
                                dynamics="${xacro.load_yaml('$(arg dynamics_path)')}"
                                accelerometer_config="${xacro.load_yaml('$(arg accelerometers_path)')}"
                                gazebo="${gazebo}"
                                hand="${hand}"
                                ee_id="${ee_id}"
                                special_connection="${special_connection}"
                                xyz_ee="${xyz_ee}"
                                rpy_ee="${rpy_ee}"
                                tcp_xyz="${tcp_xyz}"
                                tcp_rpy="${tcp_rpy}"
                                safety_distance="${safety_distance}"
                                with_sc="${with_sc}"
                                ros2_control="${ros_control_flag_for_real_hardware}"
                                robot_ip="${robot_ips_list[i]}"
                                use_fake_hardware="${use_fake_hardware}"
                                fake_sensor_commands="${fake_sensor_commands}"
                                gazebo_effort="${gazebo_effort}"
                                no_prefix="${no_prefix}"
                                arm_prefix= "${modified_prefix}"
                                description_pkg="${description_pkg}"
                                connected_to="${arm_prefixes_list[i]}_base"
                                parent="${arm_prefixes_list[i]}_base">
            </xacro:franka_robot>
            </xacro:if>
        </xacro:unless>
        <xacro:loop i="${i+1}"/>
        </xacro:unless>
    </xacro:macro>
    <xacro:loop i="0"/>

    <xacro:if value="${gazebo}">
        <xacro:mobile_fr3_duo_ros2_control mobile_robot_type="tmrv0_2"
                                            robot_types="${robot_types_list}"
                                            arm_prefixes="${arm_prefixes_list}"
                                            robot_ips="${robot_ips_list}"
                                            hand="${hand}"
                                            use_fake_hardware="${use_fake_hardware}"
                                            fake_sensor_commands="${fake_sensor_commands}"
                                            gazebo="${gazebo}"
                                            gazebo_effort="${gazebo_effort}"
                                            robot_namespace=""/>       
    </xacro:if>      
    
  </xacro:macro>
</robot>