<?xml version="1.0" ?>
<!-- =================================================================================== -->
<!-- |    This document was autogenerated by xacro from /home/yusuf/robot_workspaces/combined_ws/src/combined_robot/urdf/panther_with_franka.urdf.xacro | -->
<!-- |    EDITING THIS FILE BY HAND IS NOT RECOMMENDED                                 | -->
<!-- =================================================================================== -->
<robot name="panther_with_franka">
  <joint name="base_to_body_joint" type="fixed">
    <origin rpy="0.0 0.0 0.0" xyz="0.0 0.0 0.0"/>
    <parent link="base_link"/>
    <child link="body_link"/>
  </joint>
  <link name="base_link"/>
  <link name="body_link">
    <visual>
      <geometry>
        <mesh filename="package://husarion_ugv_description/meshes/panther/base.dae"/>
      </geometry>
    </visual>
    <collision>
      <origin rpy="0.0 0.0 0.0" xyz="0.0 0.0 0.0"/>
      <geometry>
        <mesh filename="package://husarion_ugv_description/meshes/panther/base_collision.stl"/>
      </geometry>
    </collision>
    <inertial>
      <origin rpy="0.0 0.0 0.0" xyz="-0.008 0.01 0.029"/>
      <mass value="43.0"/>
      <inertia ixx="2.630036" ixy="-0.023480" ixz="0.052320" iyy="2.463509" iyz="0.009337" izz="4.611945"/>
    </inertial>
  </link>
  <joint name="body_to_footprint_joint" type="fixed">
    <origin rpy="0.0 0.0 0.0" xyz="0.0 0.0 -0.1825"/>
    <parent link="body_link"/>
    <child link="base_footprint"/>
  </joint>
  <link name="base_footprint"/>
  <joint name="body_to_imu_joint" type="fixed">
    <origin rpy="0.0 0.0 -1.57" xyz="0.169 0.025 0.092"/>
    <parent link="body_link"/>
    <child link="imu_link"/>
  </joint>
  <link name="imu_link"/>
  <joint name="body_to_front_bumper_joint" type="fixed">
    <origin rpy="0.0 0.0 0.0" xyz="0.362 0.0 0.0"/>
    <parent link="body_link"/>
    <child link="front_bumper_link"/>
  </joint>
  <link name="front_bumper_link"/>
  <joint name="front_bumper_to_lights_channel_1_joint" type="fixed">
    <origin rpy="0.0 0.0 0.0" xyz="0.0 0.0 0.0185"/>
    <parent link="front_bumper_link"/>
    <child link="lights_channel_1_link"/>
  </joint>
  <link name="lights_channel_1_link"/>
  <joint name="body_to_rear_bumper_joint" type="fixed">
    <origin rpy="0.0 0.0 3.141592653589793" xyz="-0.362 0.0 0.0"/>
    <parent link="body_link"/>
    <child link="rear_bumper_link"/>
  </joint>
  <link name="rear_bumper_link"/>
  <joint name="rear_bumper_to_lights_channel_2_joint" type="fixed">
    <origin rpy="0.0 0.0 0.0" xyz="0.0 0.0 0.0185"/>
    <parent link="rear_bumper_link"/>
    <child link="lights_channel_2_link"/>
  </joint>
  <link name="lights_channel_2_link"/>
  <joint name="body_to_cover_joint" type="fixed">
    <origin rpy="0.0 0.0 0.0" xyz="0.0 0.0 0.14"/>
    <parent link="body_link"/>
    <child link="cover_link"/>
  </joint>
  <link name="cover_link"/>
  <joint name="cover_to_mount_joint" type="fixed">
    <origin rpy="0.0 0.0 0.0" xyz="0.0 0.0 0.0315"/>
    <parent link="cover_link"/>
    <child link="mount_link"/>
  </joint>
  <link name="mount_link"/>
  <joint name="body_to_fl_wheel_base_joint" type="fixed">
    <origin rpy="0.0 0.0 0.0" xyz="0.22 0.2575 0.0"/>
    <parent link="body_link"/>
    <child link="fl_wheel_base_link"/>
  </joint>
  <link name="fl_wheel_base_link"/>
  <joint name="fl_wheel_joint" type="continuous">
    <origin rpy="0.0 0.0 0.0" xyz="0.0 0.091 0.0"/>
    <parent link="fl_wheel_base_link"/>
    <child link="fl_wheel_link"/>
    <axis xyz="0.0 1.0 0.0"/>
    <limit effort="64.5" velocity="10.958"/>
    <dynamics damping="0.01" friction="0.1"/>
  </joint>
  <link name="fl_wheel_link">
    <visual>
      <origin rpy="0.0 0.0 0.0" xyz="0.0 0.0 0.0"/>
      <geometry>
        <mesh filename="package://husarion_ugv_description/meshes/WH01/fl_wheel.dae"/>
      </geometry>
    </visual>
    <collision>
      <origin rpy="-1.5707963267948966 0.0 0.0" xyz="0.0 0.0 0.0"/>
      <geometry>
        <cylinder length="0.14" radius="0.1825"/>
      </geometry>
    </collision>
    <inertial>
      <origin rpy="0.0 0.0 0.0" xyz="0.0 0.0 0.0"/>
      <mass value="3.0"/>
      <inertia ixx="0.02251" ixy="0.0" ixz="0.0" iyy="0.03485" iyz="0.0" izz="0.02251"/>
    </inertial>
  </link>
  <joint name="body_to_fr_wheel_base_joint" type="fixed">
    <origin rpy="0.0 0.0 0.0" xyz="0.22 -0.2575 0.0"/>
    <parent link="body_link"/>
    <child link="fr_wheel_base_link"/>
  </joint>
  <link name="fr_wheel_base_link"/>
  <joint name="fr_wheel_joint" type="continuous">
    <origin rpy="0.0 0.0 0.0" xyz="0.0 -0.091 0.0"/>
    <parent link="fr_wheel_base_link"/>
    <child link="fr_wheel_link"/>
    <axis xyz="0.0 1.0 0.0"/>
    <limit effort="64.5" velocity="10.958"/>
    <dynamics damping="0.01" friction="0.1"/>
  </joint>
  <link name="fr_wheel_link">
    <visual>
      <origin rpy="0.0 0.0 0.0" xyz="0.0 0.0 0.0"/>
      <geometry>
        <mesh filename="package://husarion_ugv_description/meshes/WH01/fr_wheel.dae"/>
      </geometry>
    </visual>
    <collision>
      <origin rpy="-1.5707963267948966 0.0 0.0" xyz="0.0 0.0 0.0"/>
      <geometry>
        <cylinder length="0.14" radius="0.1825"/>
      </geometry>
    </collision>
    <inertial>
      <origin rpy="0.0 0.0 0.0" xyz="0.0 -0.0 0.0"/>
      <mass value="3.0"/>
      <inertia ixx="0.02251" ixy="0.0" ixz="0.0" iyy="0.03485" iyz="0.0" izz="0.02251"/>
    </inertial>
  </link>
  <joint name="body_to_rl_wheel_base_joint" type="fixed">
    <origin rpy="0.0 0.0 0.0" xyz="-0.22 0.2575 0.0"/>
    <parent link="body_link"/>
    <child link="rl_wheel_base_link"/>
  </joint>
  <link name="rl_wheel_base_link"/>
  <joint name="rl_wheel_joint" type="continuous">
    <origin rpy="0.0 0.0 0.0" xyz="0.0 0.091 0.0"/>
    <parent link="rl_wheel_base_link"/>
    <child link="rl_wheel_link"/>
    <axis xyz="0.0 1.0 0.0"/>
    <limit effort="64.5" velocity="10.958"/>
    <dynamics damping="0.01" friction="0.1"/>
  </joint>
  <link name="rl_wheel_link">
    <visual>
      <origin rpy="0.0 0.0 0.0" xyz="0.0 0.0 0.0"/>
      <geometry>
        <mesh filename="package://husarion_ugv_description/meshes/WH01/rl_wheel.dae"/>
      </geometry>
    </visual>
    <collision>
      <origin rpy="-1.5707963267948966 0.0 0.0" xyz="0.0 0.0 0.0"/>
      <geometry>
        <cylinder length="0.14" radius="0.1825"/>
      </geometry>
    </collision>
    <inertial>
      <origin rpy="0.0 0.0 0.0" xyz="0.0 0.0 0.0"/>
      <mass value="3.0"/>
      <inertia ixx="0.02251" ixy="0.0" ixz="0.0" iyy="0.03485" iyz="0.0" izz="0.02251"/>
    </inertial>
  </link>
  <joint name="body_to_rr_wheel_base_joint" type="fixed">
    <origin rpy="0.0 0.0 0.0" xyz="-0.22 -0.2575 0.0"/>
    <parent link="body_link"/>
    <child link="rr_wheel_base_link"/>
  </joint>
  <link name="rr_wheel_base_link"/>
  <joint name="rr_wheel_joint" type="continuous">
    <origin rpy="0.0 0.0 0.0" xyz="0.0 -0.091 0.0"/>
    <parent link="rr_wheel_base_link"/>
    <child link="rr_wheel_link"/>
    <axis xyz="0.0 1.0 0.0"/>
    <limit effort="64.5" velocity="10.958"/>
    <dynamics damping="0.01" friction="0.1"/>
  </joint>
  <link name="rr_wheel_link">
    <visual>
      <origin rpy="0.0 0.0 0.0" xyz="0.0 0.0 0.0"/>
      <geometry>
        <mesh filename="package://husarion_ugv_description/meshes/WH01/rr_wheel.dae"/>
      </geometry>
    </visual>
    <collision>
      <origin rpy="-1.5707963267948966 0.0 0.0" xyz="0.0 0.0 0.0"/>
      <geometry>
        <cylinder length="0.14" radius="0.1825"/>
      </geometry>
    </collision>
    <inertial>
      <origin rpy="0.0 0.0 0.0" xyz="0.0 -0.0 0.0"/>
      <mass value="3.0"/>
      <inertia ixx="0.02251" ixy="0.0" ixz="0.0" iyy="0.03485" iyz="0.0" izz="0.02251"/>
    </inertial>
  </link>
  <ros2_control name="panther_system" type="system">
    <hardware>
      <plugin>husarion_ugv_hardware_interfaces/PantherSystem</plugin>
      <param name="encoder_resolution">1600</param>
      <param name="gear_ratio">30.08</param>
      <param name="gearbox_efficiency">0.75</param>
      <!-- Same as set in the Roboteq driver (TNM parameter) -->
      <param name="motor_torque_constant">0.11</param>
      <!-- Max RPM speed set in the Roboteq driver (MXRPM parameter) -->
      <param name="max_rpm_motor_speed">3600.0</param>
      <param name="can_interface_name">robot_can</param>
      <param name="master_can_id">3</param>
      <param name="front_driver_can_id">1</param>
      <param name="rear_driver_can_id">2</param>
      <param name="sdo_operation_timeout_ms">100</param>
      <!-- Depends on frequency of the controller, more critical motors state are sent with
            higher frequency, other parameters are sent with lower, here allowed time is set
            to be expected period +50% margin -->
      <param name="pdo_motor_states_timeout_ms">15</param>
      <param name="pdo_driver_state_timeout_ms">75</param>
      <!-- It will be rounded to the closest value taking into account current controller frequency -->
      <param name="driver_states_update_frequency">20.0</param>
      <param name="max_roboteq_initialization_attempts">5</param>
      <param name="max_roboteq_activation_attempts">5</param>
      <!-- TODO after all tests update parameters, these ones are quite high for the worst case scenario -->
      <param name="max_write_pdo_cmds_errors_count">2</param>
      <param name="max_read_pdo_motor_states_errors_count">2</param>
      <param name="max_read_pdo_driver_state_errors_count">2</param>
    </hardware>
    <joint name="fl_wheel_joint">
      <command_interface name="velocity"/>
      <state_interface name="position"/>
      <state_interface name="velocity"/>
      <state_interface name="effort"/>
    </joint>
    <joint name="fr_wheel_joint">
      <command_interface name="velocity"/>
      <state_interface name="position"/>
      <state_interface name="velocity"/>
      <state_interface name="effort"/>
    </joint>
    <joint name="rl_wheel_joint">
      <command_interface name="velocity"/>
      <state_interface name="position"/>
      <state_interface name="velocity"/>
      <state_interface name="effort"/>
    </joint>
    <joint name="rr_wheel_joint">
      <command_interface name="velocity"/>
      <state_interface name="position"/>
      <state_interface name="velocity"/>
      <state_interface name="effort"/>
    </joint>
  </ros2_control>
  <ros2_control name="imu" type="sensor">
    <hardware>
      <plugin>husarion_ugv_hardware_interfaces/PhidgetImuSensor</plugin>
      <param name="serial">-1</param>
      <param name="hub_port">0</param>
      <param name="data_interval_ms">8</param>
      <param name="callback_delta_epsilon_ms">1</param>
      <!-- Madgwick Filter Params -->
      <param name="gain">0.00304</param>
      <param name="zeta">0.00151</param>
      <param name="mag_bias_x">0.0</param>
      <param name="mag_bias_y">0.0</param>
      <param name="mag_bias_z">0.0</param>
      <param name="use_mag">true</param>
      <param name="stateless">false</param>
      <param name="remove_gravity_vector">false</param>
      <param name="world_frame">enu</param>
    </hardware>
    <sensor name="imu">
      <state_interface name="orientation.x"/>
      <state_interface name="orientation.y"/>
      <state_interface name="orientation.z"/>
      <state_interface name="orientation.w"/>
      <state_interface name="angular_velocity.x"/>
      <state_interface name="angular_velocity.y"/>
      <state_interface name="angular_velocity.z"/>
      <state_interface name="linear_acceleration.x"/>
      <state_interface name="linear_acceleration.y"/>
      <state_interface name="linear_acceleration.z"/>
    </sensor>
  </ros2_control>
  <!-- İyi Domates Sepeti (yeşil, sağ arka) -->
  <link name="good_basket_link">
    <visual>
      <origin rpy="0 0 0" xyz="0 0 0"/>
      <geometry>
        <mesh filename="file:///home/yusuf/.gz/models/fruit_crate/meshes/basket.dae" scale="0.0040 0.0049 0.0049"/>
      </geometry>
      <material name="crate_brown">
        <color rgba="0.7 0.5 0.3 1.0"/>
      </material>
    </visual>
    <collision name="basket_floor_collision">
      <origin rpy="0 0 0" xyz="0 0 0.22"/>
      <geometry>
        <box size="0.46 0.38 0.04"/>
      </geometry>
    </collision>
  </link>
  <joint name="good_basket_joint" type="fixed">
    <parent link="base_link"/>
    <child link="good_basket_link"/>
    <origin rpy="0 0 1.5708" xyz="-0.55 0.0 -0.12"/>
  </joint>
  <link name="bad_basket_link">
    <visual>
      <origin rpy="0 0 0" xyz="0 0 0"/>
      <geometry>
        <mesh filename="file:///home/yusuf/.gz/models/fruit_crate/meshes/basket.dae" scale="0.0040 0.0049 0.0049"/>
      </geometry>
      <material name="crate_brown">
        <color rgba="0.7 0.5 0.3 1.0"/>
      </material>
    </visual>
    <collision name="basket_floor_collision">
      <origin rpy="0 0 0" xyz="0 0 0.22"/>
      <geometry>
        <box size="0.46 0.38 0.04"/>
      </geometry>
    </collision>
  </link>
  <joint name="bad_basket_joint" type="fixed">
    <parent link="base_link"/>
    <child link="bad_basket_link"/>
    <origin rpy="0 0 1.5708" xyz="-0.90 0.0 -0.12"/>
  </joint>
  <!-- <xacro:if value="${component_name == ''}">
      <xacro:property name="component_name" value="rplidar" />
    </xacro:if> -->
  <!-- ^ removed for compatibility with hw driver -->
  <!-- ^ in case no name is provided, generate "..._link" instead of just "link" -->
  <joint name="mount_to_rplidar_joint" type="fixed">
    <origin rpy="0.0 0.0 0.0" xyz="0.2 0.0 0.0"/>
    <parent link="mount_link"/>
    <child link="rplidar_link"/>
  </joint>
  <link name="rplidar_link">
    <!-- <visual>
        <origin xyz="0.0 0.0 0.0" rpy="0.0 0.0 0.0" />
        <geometry>
          <mesh filename="package://husarion_components_description/meshes/rplidar/${mesh}" />
        </geometry>
      </visual> -->
    <!-- TODO Remove simple visuals when mesh is ready -->
    <visual>
      <origin rpy="0.0 0.0 0.0" xyz="0.0 0.0 0.02065"/>
      <geometry>
        <box size="0.0556 0.0556 0.0413"/>
      </geometry>
      <material name="LightGrey">
        <color rgba="0.6 0.6 0.6 1.0"/>
      </material>
    </visual>
    <collision>
      <origin rpy="0.0 0.0 0.0" xyz="0.0 0.0 0.02065"/>
      <geometry>
        <box size="0.0556 0.0556 0.0413"/>
      </geometry>
    </collision>
    <inertial>
      <origin rpy="0.0 0.0 0.0" xyz="0.0 0.0 0.022473700000000003"/>
      <mass value="0.115033"/>
      <inertia ixx="0.00004115765" ixy="0.0" ixz="0.0" iyy="0.00004115765" iyz="0.0" izz="0.00004956023"/>
    </inertial>
  </link>
  <joint name="rplidar_to_laser_joint" type="fixed">
    <origin rpy="0.0 0.0 3.141592653589793" xyz="0.0 0.0 0.0305"/>
    <parent link="rplidar_link"/>
    <child link="laser"/>
  </joint>
  <link name="laser"/>
  <gazebo reference="laser">
    <sensor name="lidar" type="gpu_lidar">
      <always_on>true</always_on>
      <update_rate>10</update_rate>
      <visualize>true</visualize>
      <topic>scan</topic>
      <gz_frame_id>laser</gz_frame_id>
      <ray>
        <scan>
          <horizontal>
            <samples>3000</samples>
            <resolution>1</resolution>
            <min_angle>-3.141592653589793</min_angle>
            <max_angle>3.141592653589793</max_angle>
          </horizontal>
        </scan>
        <range>
          <min>0.05</min>
          <max>40.0</max>
          <resolution>0.01</resolution>
        </range>
        <noise>
          <type>gaussian</type>
          <mean>0.0</mean>
          <stddev>0.015</stddev>
        </noise>
      </ray>
    </sensor>
  </gazebo>
  <!-- safety_distance: Minimum safety distance in [m] by which the collision volumes are expanded and which is enforced during robot motions -->
  <!-- robot_type: Namespace of the robot arm. Serves to differentiate between arms in case of multiple instances. -->
  <!-- joint_limits: description of the joint limits that comes from a YAML file. Example definition: ${xacro.load_yaml('$(find franka_description)/robots/fr3/joint_limits.yaml')} -->
  <!-- kinematics: description of the kinematics that comes from a YAML file. Example definition: ${xacro.load_yaml('$(find franka_description)/robots/fr3/kinematics.yaml')} -->
  <!-- inertials: description of the inertials that comes from a YAML file. Example definition: ${xacro.load_yaml('$(find franka_description)/robots/fr3/inertials.yaml')} -->
  <!-- dynamics: description of the dynamics that comes from a YAML file. Example definition: ${xacro.load_yaml('$(find franka_description)/robots/fr3/dynamics.yaml')} -->
  <!-- sub-link defining detailed meshes for collision with environment -->
  <link name="fr3_link0">
    <visual name="fr3_link0_visual">
      <geometry>
        <mesh filename="package://franka_description/meshes/robots/fr3/visual/link0.dae"/>
      </geometry>
    </visual>
    <collision name="fr3_link0_collision">
      <geometry>
        <mesh filename="package://franka_description/meshes/robots/fr3/collision/link0.stl"/>
      </geometry>
    </collision>
    <inertial>
      <origin rpy="0 0 0" xyz="-0.0172 0.0004 0.0745"/>
      <mass value="2.3966"/>
      <inertia ixx="0.009" ixy="0.0" ixz="0.002" iyy="0.0115" iyz="0.0" izz="0.0085"/>
    </inertial>
  </link>
  <link name="fr3_link0_accelerometer_top">
      </link>
  <joint name="fr3_link0_accelerometer_top_joint" type="fixed">
    <origin rpy="3.1416 0.0 0.0" xyz="-0.017402 -0.007872 0.04715"/>
    <parent link="fr3_link0"/>
    <child link="fr3_link0_accelerometer_top"/>
  </joint>
  <link name="fr3_link0_accelerometer_bottom">
      </link>
  <joint name="fr3_link0_accelerometer_bottom_joint" type="fixed">
    <origin rpy="0.0 0.0 -1.5708" xyz="-0.019739 0.0015506 0.05075"/>
    <parent link="fr3_link0"/>
    <child link="fr3_link0_accelerometer_bottom"/>
  </joint>
  <!-- sub-link defining detailed meshes for collision with environment -->
  <link name="fr3_link1">
    <visual name="fr3_link1_visual">
      <geometry>
        <mesh filename="package://franka_description/meshes/robots/fr3/visual/link1.dae"/>
      </geometry>
    </visual>
    <collision name="fr3_link1_collision">
      <geometry>
        <mesh filename="package://franka_description/meshes/robots/fr3/collision/link1.stl"/>
      </geometry>
    </collision>
    <inertial>
      <origin rpy="0 0 0" xyz="0.0000004128 -0.0181251324 -0.0386035970"/>
      <mass value="2.9274653454"/>
      <inertia ixx="0.023927316485107913" ixy="1.3317903455714081e-05" ixz="-0.00011404774918616684" iyy="0.0224821613275756" iyz="-0.0019950320628240115" izz="0.006350098258530016"/>
    </inertial>
  </link>
  <link name="fr3_link1_accelerometer_top">
      </link>
  <joint name="fr3_link1_accelerometer_top_joint" type="fixed">
    <origin rpy="-1.5708 0.0 3.1416" xyz="0.017402 -0.093352 -0.00787"/>
    <parent link="fr3_link1"/>
    <child link="fr3_link1_accelerometer_top"/>
  </joint>
  <link name="fr3_link1_accelerometer_bottom">
      </link>
  <joint name="fr3_link1_accelerometer_bottom_joint" type="fixed">
    <origin rpy="-1.5708 1.5708 0.0" xyz="0.01974 -0.08975 0.00155"/>
    <parent link="fr3_link1"/>
    <child link="fr3_link1_accelerometer_bottom"/>
  </joint>
  <joint name="fr3_joint1" type="revolute">
    <origin rpy="0 0 0" xyz="0 0 0.333"/>
    <parent link="fr3_link0"/>
    <child link="fr3_link1"/>
    <axis xyz="0 0 1"/>
    <limit effort="87.0" lower="-2.9007" upper="2.9007" velocity="2.62"/>
    <safety_controller k_position="100.0" k_velocity="40.0" soft_lower_limit="-2.9007" soft_upper_limit="2.9007"/>
    <position_based_velocity_limits deceleration_limit="6.0" velocity_offset="0.652"/>
    <dynamics D="1" K="7000" damping="0.003" friction="0.2" gear_ratio="120.0" motor_inertia="4.206399e-05" mu_coulomb="0" mu_viscous="16"/>
  </joint>
  <!-- sub-link defining detailed meshes for collision with environment -->
  <link name="fr3_link2">
    <visual name="fr3_link2_visual">
      <geometry>
        <mesh filename="package://franka_description/meshes/robots/fr3/visual/link2.dae"/>
      </geometry>
    </visual>
    <collision name="fr3_link2_collision">
      <geometry>
        <mesh filename="package://franka_description/meshes/robots/fr3/collision/link2.stl"/>
      </geometry>
    </collision>
    <inertial>
      <origin rpy="0 0 0" xyz="0.0031828864 -0.0743221644 0.0088146084"/>
      <mass value="2.9355370338"/>
      <inertia ixx="0.041938946257609425" ixy="0.00020257331521090626" ixz="0.004077784227179924" iyy="0.02514514885014724" iyz="-0.0042252158006570156" izz="0.06170214472888839"/>
    </inertial>
  </link>
  <link name="fr3_link2_accelerometer_top">
      </link>
  <joint name="fr3_link2_accelerometer_top_joint" type="fixed">
    <origin rpy="1.5708 0.0 3.1416" xyz="0.017403 -0.11715 0.00787"/>
    <parent link="fr3_link2"/>
    <child link="fr3_link2_accelerometer_top"/>
  </joint>
  <link name="fr3_link2_accelerometer_bottom">
      </link>
  <joint name="fr3_link2_accelerometer_bottom_joint" type="fixed">
    <origin rpy="1.5708 -1.5708 0.0" xyz="0.019737 -0.11875 -0.00155"/>
    <parent link="fr3_link2"/>
    <child link="fr3_link2_accelerometer_bottom"/>
  </joint>
  <joint name="fr3_joint2" type="revolute">
    <origin rpy="-1.570796326794897 0 0" xyz="0 0 0"/>
    <parent link="fr3_link1"/>
    <child link="fr3_link2"/>
    <axis xyz="0 0 1"/>
    <limit effort="87.0" lower="-1.8361" upper="1.8361" velocity="2.62"/>
    <safety_controller k_position="100.0" k_velocity="40.0" soft_lower_limit="-1.8361" soft_upper_limit="1.8361"/>
    <position_based_velocity_limits deceleration_limit="2.585" velocity_offset="0.25"/>
    <dynamics D="1" K="7000" damping="0.003" friction="0.2" gear_ratio="120.0" motor_inertia="4.206399e-05" mu_coulomb="0" mu_viscous="16"/>
  </joint>
  <!-- sub-link defining detailed meshes for collision with environment -->
  <link name="fr3_link3">
    <visual name="fr3_link3_visual">
      <geometry>
        <mesh filename="package://franka_description/meshes/robots/fr3/visual/link3.dae"/>
      </geometry>
    </visual>
    <collision name="fr3_link3_collision">
      <geometry>
        <mesh filename="package://franka_description/meshes/robots/fr3/collision/link3.stl"/>
      </geometry>
    </collision>
    <inertial>
      <origin rpy="0 0 0" xyz="0.0407015686 -0.0048200565 -0.0289730823"/>
      <mass value="2.2449013699"/>
      <inertia ixx="0.02410142547240885" ixy="0.002404694559042109" ixz="-0.002856269270114313" iyy="0.01974053266708178" iyz="-0.002104212683891874" izz="0.019044494482244823"/>
    </inertial>
  </link>
  <link name="fr3_link3_accelerometer_top">
      </link>
  <joint name="fr3_link3_accelerometer_top_joint" type="fixed">
    <origin rpy="-1.5708 0.0 0.0" xyz="0.065099 0.077352 -0.00787"/>
    <parent link="fr3_link3"/>
    <child link="fr3_link3_accelerometer_top"/>
  </joint>
  <link name="fr3_link3_accelerometer_bottom">
      </link>
  <joint name="fr3_link3_accelerometer_bottom_joint" type="fixed">
    <origin rpy="1.5708 1.5708 0.0" xyz="0.062769 0.073756 0.00155"/>
    <parent link="fr3_link3"/>
    <child link="fr3_link3_accelerometer_bottom"/>
  </joint>
  <joint name="fr3_joint3" type="revolute">
    <origin rpy="1.570796326794897 0 0" xyz="0 -0.316 0"/>
    <parent link="fr3_link2"/>
    <child link="fr3_link3"/>
    <axis xyz="0 0 1"/>
    <limit effort="87.0" lower="-2.9007" upper="2.9007" velocity="2.62"/>
    <safety_controller k_position="100.0" k_velocity="40.0" soft_lower_limit="-2.9007" soft_upper_limit="2.9007"/>
    <position_based_velocity_limits deceleration_limit="3.5" velocity_offset="0.2005"/>
    <dynamics D="1" K="7000" damping="0.003" friction="0.2" gear_ratio="120.0" motor_inertia="3.211626e-05" mu_coulomb="0" mu_viscous="16"/>
  </joint>
  <!-- sub-link defining detailed meshes for collision with environment -->
  <link name="fr3_link4">
    <visual name="fr3_link4_visual">
      <geometry>
        <mesh filename="package://franka_description/meshes/robots/fr3/visual/link4.dae"/>
      </geometry>
    </visual>
    <collision name="fr3_link4_collision">
      <geometry>
        <mesh filename="package://franka_description/meshes/robots/fr3/collision/link4.stl"/>
      </geometry>
    </collision>
    <inertial>
      <origin rpy="0 0 0" xyz="-0.0459100965 0.0630492960 -0.0085187868"/>
      <mass value="2.6155955791"/>
      <inertia ixx="0.03452998321913202" ixy="0.01322552265982813" ixz="0.01015142998484113" iyy="0.028881621933049058" iyz="-0.0009762833870704552" izz="0.04125471171146641"/>
    </inertial>
  </link>
  <link name="fr3_link4_accelerometer_top">
      </link>
  <joint name="fr3_link4_accelerometer_top_joint" type="fixed">
    <origin rpy="-1.5708 0.0 -3.1416" xyz="-0.0651 0.046252 -0.00787"/>
    <parent link="fr3_link4"/>
    <child link="fr3_link4_accelerometer_top"/>
  </joint>
  <link name="fr3_link4_accelerometer_bottom">
      </link>
  <joint name="fr3_link4_accelerometer_bottom_joint" type="fixed">
    <origin rpy="-1.5708 1.5708 0.0" xyz="-0.062775 0.049753 0.00155"/>
    <parent link="fr3_link4"/>
    <child link="fr3_link4_accelerometer_bottom"/>
  </joint>
  <joint name="fr3_joint4" type="revolute">
    <origin rpy="1.570796326794897 0 0" xyz="0.0825 0 0"/>
    <parent link="fr3_link3"/>
    <child link="fr3_link4"/>
    <axis xyz="0 0 1"/>
    <limit effort="87.0" lower="-3.077" upper="-0.1169" velocity="2.62"/>
    <safety_controller k_position="100.0" k_velocity="40.0" soft_lower_limit="-3.077" soft_upper_limit="-0.1169"/>
    <position_based_velocity_limits deceleration_limit="4.0" velocity_offset="0.3542"/>
    <dynamics D="1" K="7000" damping="0.003" friction="0.2" gear_ratio="120.0" motor_inertia="3.211626e-05" mu_coulomb="0" mu_viscous="16"/>
  </joint>
  <!-- sub-link defining detailed meshes for collision with environment -->
  <link name="fr3_link5">
    <visual name="fr3_link5_visual">
      <geometry>
        <mesh filename="package://franka_description/meshes/robots/fr3/visual/link5.dae"/>
      </geometry>
    </visual>
    <collision name="fr3_link5_collision">
      <geometry>
        <mesh filename="package://franka_description/meshes/robots/fr3/collision/link5.stl"/>
      </geometry>
    </collision>
    <inertial>
      <origin rpy="0 0 0" xyz="-0.0016039605 0.0292536262 -0.0972965990"/>
      <mass value="2.3271207594"/>
      <inertia ixx="0.051610278463662895" ixy="-0.005715173387783472" ixz="-0.0035673167625872135" iyy="0.04787729713371481" iyz="0.010673985108535986" izz="0.016423625579357254"/>
    </inertial>
  </link>
  <link name="fr3_link5_accelerometer_top">
      </link>
  <joint name="fr3_link5_accelerometer_top_joint" type="fixed">
    <origin rpy="-1.5708 0.0 0.0" xyz="-0.017363 0.085872 -0.00795"/>
    <parent link="fr3_link5"/>
    <child link="fr3_link5_accelerometer_top"/>
  </joint>
  <link name="fr3_link5_accelerometer_bottom">
      </link>
  <joint name="fr3_link5_accelerometer_bottom_joint" type="fixed">
    <origin rpy="1.5708 1.5708 0.0" xyz="-0.019742 0.082275 0.00146"/>
    <parent link="fr3_link5"/>
    <child link="fr3_link5_accelerometer_bottom"/>
  </joint>
  <joint name="fr3_joint5" type="revolute">
    <origin rpy="-1.570796326794897 0 0" xyz="-0.0825 0.384 0"/>
    <parent link="fr3_link4"/>
    <child link="fr3_link5"/>
    <axis xyz="0 0 1"/>
    <limit effort="12.0" lower="-2.8763" upper="2.8763" velocity="5.26"/>
    <safety_controller k_position="100.0" k_velocity="40.0" soft_lower_limit="-2.8763" soft_upper_limit="2.8763"/>
    <position_based_velocity_limits deceleration_limit="17.0" velocity_offset="0.5738"/>
    <dynamics D="1" K="7000" damping="0.003" friction="0.2" gear_ratio="80.0" motor_inertia="3.211626e-05" mu_coulomb="0" mu_viscous="16"/>
  </joint>
  <!-- sub-link defining detailed meshes for collision with environment -->
  <link name="fr3_link6">
    <visual name="fr3_link6_visual">
      <geometry>
        <mesh filename="package://franka_description/meshes/robots/fr3/visual/link6.dae"/>
      </geometry>
    </visual>
    <collision name="fr3_link6_collision">
      <geometry>
        <mesh filename="package://franka_description/meshes/robots/fr3/collision/link6.stl"/>
      </geometry>
    </collision>
    <inertial>
      <origin rpy="0 0 0" xyz="0.0597131221 -0.0410294666 -0.0101692726"/>
      <mass value="1.8170376524"/>
      <inertia ixx="0.005412333594383447" ixy="0.006193456360285834" ixz="0.0014219289306117652" iyy="0.014058329545509979" iyz="-0.0013140753741120031" izz="0.016080817924212554"/>
    </inertial>
  </link>
  <joint name="fr3_joint6" type="revolute">
    <origin rpy="1.570796326794897 0 0" xyz="0 0 0"/>
    <parent link="fr3_link5"/>
    <child link="fr3_link6"/>
    <axis xyz="0 0 1"/>
    <limit effort="12.0" lower="0.4398" upper="4.6216" velocity="4.18"/>
    <safety_controller k_position="100.0" k_velocity="40.0" soft_lower_limit="0.4398" soft_upper_limit="4.6216"/>
    <position_based_velocity_limits deceleration_limit="5.5" velocity_offset="0.4885"/>
    <dynamics D="1" K="7000" damping="0.003" friction="0.2" gear_ratio="80.0" motor_inertia="3.211626e-05" mu_coulomb="0" mu_viscous="16"/>
  </joint>
  <!-- sub-link defining detailed meshes for collision with environment -->
  <link name="fr3_link7">
    <visual name="fr3_link7_visual">
      <geometry>
        <mesh filename="package://franka_description/meshes/robots/fr3/visual/link7.dae"/>
      </geometry>
    </visual>
    <collision name="fr3_link7_collision">
      <geometry>
        <mesh filename="package://franka_description/meshes/robots/fr3/collision/link7.stl"/>
      </geometry>
    </collision>
    <inertial>
      <origin rpy="0 0 0" xyz="0.0045225817 0.0086261921 -0.0161633251"/>
      <mass value="0.6271432862"/>
      <inertia ixx="0.00021092389150104718" ixy="-2.433299114461931e-05" ixz="4.564480393778983e-05" iyy="0.00017718568002411474" iyz="8.744070223226438e-05" izz="5.993190599659971e-05"/>
    </inertial>
  </link>
  <joint name="fr3_joint7" type="revolute">
    <origin rpy="1.570796326794897 0 0" xyz="0.088 0 0"/>
    <parent link="fr3_link6"/>
    <child link="fr3_link7"/>
    <axis xyz="0 0 1"/>
    <limit effort="12.0" lower="-3.0508" upper="3.0508" velocity="5.26"/>
    <safety_controller k_position="100.0" k_velocity="40.0" soft_lower_limit="-3.0508" soft_upper_limit="3.0508"/>
    <position_based_velocity_limits deceleration_limit="17.0" velocity_offset="0.4592"/>
    <dynamics D="1" K="7000" damping="0.003" friction="0.2" gear_ratio="80.0" motor_inertia="3.211626e-05" mu_coulomb="0" mu_viscous="16"/>
  </joint>
  <link name="fr3_link8"/>
  <joint name="fr3_joint8" type="fixed">
    <origin rpy="0 0 0" xyz="0 0 0.107"/>
    <parent link="fr3_link7"/>
    <child link="fr3_link8"/>
  </joint>
  <joint name="fr3_hand_joint" type="fixed">
    <parent link="fr3_link8"/>
    <child link="fr3_hand"/>
    <origin rpy="0 0 0" xyz="0 0 0"/>
  </joint>
  <!-- sub-link defining detailed meshes for collision with environment -->
  <link name="fr3_hand">
    <visual name="fr3_hand_visual">
      <geometry>
        <mesh filename="package://franka_description/meshes/robot_ee/franka_hand_white/visual/hand.dae"/>
      </geometry>
    </visual>
    <collision name="fr3_hand_collision">
      <geometry>
        <mesh filename="package://franka_description/meshes/robot_ee/franka_hand_white/collision/hand.stl"/>
      </geometry>
    </collision>
    <inertial>
      <origin rpy="0 0 0" xyz="-0.0000376 0.0119128 0.0207260"/>
      <mass value="0.6544"/>
      <inertia ixx="0.00186" ixy="0.0" ixz="0.0" iyy="0.0003" iyz="-2e-05" izz="0.00174"/>
    </inertial>
  </link>
  <!-- Define the hand_tcp frame -->
  <link name="fr3_hand_tcp"/>
  <joint name="fr3_hand_tcp_joint" type="fixed">
    <origin rpy="0 0 0" xyz="0 0 0"/>
    <parent link="fr3_hand"/>
    <child link="fr3_hand_tcp"/>
  </joint>
  <link name="fr3_leftfinger">
    <visual name="fr3_leftfinger_visual">
      <geometry>
        <mesh filename="package://franka_description/meshes/robot_ee/franka_hand_white/visual/finger.dae"/>
      </geometry>
    </visual>
    <!-- screw mount -->
    <collision>
      <origin rpy="0 0 0" xyz="0 18.5e-3 11e-3"/>
      <geometry>
        <box size="22e-3 15e-3 20e-3"/>
      </geometry>
    </collision>
    <!-- cartriage sledge -->
    <collision>
      <origin rpy="0 0 0" xyz="0 6.8e-3 2.2e-3"/>
      <geometry>
        <box size="22e-3 8.8e-3 3.8e-3"/>
      </geometry>
    </collision>
    <!-- diagonal finger -->
    <collision>
      <origin rpy="0.5235987755982988 0 0" xyz="0 15.9e-3 28.35e-3"/>
      <geometry>
        <box size="17.5e-3 7e-3 23.5e-3"/>
      </geometry>
    </collision>
    <!-- rubber tip with which to grasp -->
    <collision>
      <origin rpy="0 0 0" xyz="0 7.58e-3 45.25e-3"/>
      <geometry>
        <box size="17.5e-3 15.2e-3 18.5e-3"/>
      </geometry>
    </collision>
    <inertial>
      <origin rpy="0 0 0" xyz="0 0.0152850 0.0219675"/>
      <mass value="0.0291"/>
      <inertia ixx="8.49e-06" ixy="0.0" ixz="0.0" iyy="8.53e-06" iyz="-1.06e-06" izz="1.77e-06"/>
    </inertial>
  </link>
  <link name="fr3_rightfinger">
    <visual name="fr3_rightfinger_visual">
      <origin rpy="0 0 0" xyz="0 0 0"/>
      <geometry>
        <mesh filename="package://franka_description/meshes/robot_ee/franka_hand_white/visual/finger.dae"/>
      </geometry>
    </visual>
    <!-- screw mount -->
    <collision>
      <origin rpy="0 0 0" xyz="0 18.5e-3 11e-3"/>
      <geometry>
        <box size="22e-3 15e-3 20e-3"/>
      </geometry>
    </collision>
    <!-- cartriage sledge -->
    <collision>
      <origin rpy="0 0 0" xyz="0 6.8e-3 2.2e-3"/>
      <geometry>
        <box size="22e-3 8.8e-3 3.8e-3"/>
      </geometry>
    </collision>
    <!-- diagonal finger -->
    <collision>
      <origin rpy="-0.5235987755982988 0 3.141592653589793" xyz="0 15.9e-3 28.35e-3"/>
      <geometry>
        <box size="17.5e-3 7e-3 23.5e-3"/>
      </geometry>
    </collision>
    <!-- rubber tip with which to grasp -->
    <collision>
      <origin rpy="0 0 0" xyz="0 7.58e-3 45.25e-3"/>
      <geometry>
        <box size="17.5e-3 15.2e-3 18.5e-3"/>
      </geometry>
    </collision>
    <inertial>
      <origin rpy="0 0 0" xyz="0 0.0152850 0.0219675"/>
      <mass value="0.0291"/>
      <inertia ixx="8.49e-06" ixy="0.0" ixz="0.0" iyy="8.53e-06" iyz="-1.06e-06" izz="1.77e-06"/>
    </inertial>
  </link>
  <joint name="fr3_finger_joint1" type="prismatic">
    <parent link="fr3_hand"/>
    <child link="fr3_leftfinger"/>
    <origin rpy="0 0 0" xyz="0 0 0.0584"/>
    <axis xyz="0 1 0"/>
    <limit effort="100" lower="0.0" upper="0.04" velocity="0.2"/>
    <dynamics damping="0.3"/>
  </joint>
  <joint name="fr3_finger_joint2" type="prismatic">
    <parent link="fr3_hand"/>
    <child link="fr3_rightfinger"/>
    <origin rpy="0 0 3.141592653589793" xyz="0 0 0.0584"/>
    <axis xyz="0 1 0"/>
    <limit effort="100" lower="0.0" upper="0.04" velocity="0.2"/>
    <dynamics damping="0.3"/>
  </joint>
  <gazebo reference="fr3_joint1">
    <!-- Needed for ODE to output external wrenches on joints -->
    <provideFeedback>true</provideFeedback>
  </gazebo>
  <transmission name="fr3_joint1_transmission">
    <type>transmission_interface/SimpleTransmission</type>
    <joint name="fr3_joint1">
      <hardwareInterface>hardware_interface/PositionJointInterface</hardwareInterface>
    </joint>
    <actuator name="fr3_joint1_motor">
      <hardwareInterface>hardware_interface/PositionJointInterface</hardwareInterface>
    </actuator>
  </transmission>
  <gazebo reference="fr3_joint2">
    <!-- Needed for ODE to output external wrenches on joints -->
    <provideFeedback>true</provideFeedback>
  </gazebo>
  <transmission name="fr3_joint2_transmission">
    <type>transmission_interface/SimpleTransmission</type>
    <joint name="fr3_joint2">
      <hardwareInterface>hardware_interface/PositionJointInterface</hardwareInterface>
    </joint>
    <actuator name="fr3_joint2_motor">
      <hardwareInterface>hardware_interface/PositionJointInterface</hardwareInterface>
    </actuator>
  </transmission>
  <gazebo reference="fr3_joint3">
    <!-- Needed for ODE to output external wrenches on joints -->
    <provideFeedback>true</provideFeedback>
  </gazebo>
  <transmission name="fr3_joint3_transmission">
    <type>transmission_interface/SimpleTransmission</type>
    <joint name="fr3_joint3">
      <hardwareInterface>hardware_interface/PositionJointInterface</hardwareInterface>
    </joint>
    <actuator name="fr3_joint3_motor">
      <hardwareInterface>hardware_interface/PositionJointInterface</hardwareInterface>
    </actuator>
  </transmission>
  <gazebo reference="fr3_joint4">
    <!-- Needed for ODE to output external wrenches on joints -->
    <provideFeedback>true</provideFeedback>
  </gazebo>
  <transmission name="fr3_joint4_transmission">
    <type>transmission_interface/SimpleTransmission</type>
    <joint name="fr3_joint4">
      <hardwareInterface>hardware_interface/PositionJointInterface</hardwareInterface>
    </joint>
    <actuator name="fr3_joint4_motor">
      <hardwareInterface>hardware_interface/PositionJointInterface</hardwareInterface>
    </actuator>
  </transmission>
  <gazebo reference="fr3_joint5">
    <!-- Needed for ODE to output external wrenches on joints -->
    <provideFeedback>true</provideFeedback>
  </gazebo>
  <transmission name="fr3_joint5_transmission">
    <type>transmission_interface/SimpleTransmission</type>
    <joint name="fr3_joint5">
      <hardwareInterface>hardware_interface/PositionJointInterface</hardwareInterface>
    </joint>
    <actuator name="fr3_joint5_motor">
      <hardwareInterface>hardware_interface/PositionJointInterface</hardwareInterface>
    </actuator>
  </transmission>
  <gazebo reference="fr3_joint6">
    <!-- Needed for ODE to output external wrenches on joints -->
    <provideFeedback>true</provideFeedback>
  </gazebo>
  <transmission name="fr3_joint6_transmission">
    <type>transmission_interface/SimpleTransmission</type>
    <joint name="fr3_joint6">
      <hardwareInterface>hardware_interface/PositionJointInterface</hardwareInterface>
    </joint>
    <actuator name="fr3_joint6_motor">
      <hardwareInterface>hardware_interface/PositionJointInterface</hardwareInterface>
    </actuator>
  </transmission>
  <gazebo reference="fr3_joint7">
    <!-- Needed for ODE to output external wrenches on joints -->
    <provideFeedback>true</provideFeedback>
  </gazebo>
  <transmission name="fr3_joint7_transmission">
    <type>transmission_interface/SimpleTransmission</type>
    <joint name="fr3_joint7">
      <hardwareInterface>hardware_interface/PositionJointInterface</hardwareInterface>
    </joint>
    <actuator name="fr3_joint7_motor">
      <hardwareInterface>hardware_interface/PositionJointInterface</hardwareInterface>
    </actuator>
  </transmission>
  <gazebo reference="fr3_joint1">
    <!-- Needed for ODE to output external wrenches on joints -->
    <provideFeedback>true</provideFeedback>
  </gazebo>
  <transmission name="fr3_joint1_transmission">
    <type>transmission_interface/SimpleTransmission</type>
    <joint name="fr3_joint1">
      <hardwareInterface>hardware_interface/VelocityJointInterface</hardwareInterface>
    </joint>
    <actuator name="fr3_joint1_motor">
      <hardwareInterface>hardware_interface/VelocityJointInterface</hardwareInterface>
    </actuator>
  </transmission>
  <gazebo reference="fr3_joint2">
    <!-- Needed for ODE to output external wrenches on joints -->
    <provideFeedback>true</provideFeedback>
  </gazebo>
  <transmission name="fr3_joint2_transmission">
    <type>transmission_interface/SimpleTransmission</type>
    <joint name="fr3_joint2">
      <hardwareInterface>hardware_interface/VelocityJointInterface</hardwareInterface>
    </joint>
    <actuator name="fr3_joint2_motor">
      <hardwareInterface>hardware_interface/VelocityJointInterface</hardwareInterface>
    </actuator>
  </transmission>
  <gazebo reference="fr3_joint3">
    <!-- Needed for ODE to output external wrenches on joints -->
    <provideFeedback>true</provideFeedback>
  </gazebo>
  <transmission name="fr3_joint3_transmission">
    <type>transmission_interface/SimpleTransmission</type>
    <joint name="fr3_joint3">
      <hardwareInterface>hardware_interface/VelocityJointInterface</hardwareInterface>
    </joint>
    <actuator name="fr3_joint3_motor">
      <hardwareInterface>hardware_interface/VelocityJointInterface</hardwareInterface>
    </actuator>
  </transmission>
  <gazebo reference="fr3_joint4">
    <!-- Needed for ODE to output external wrenches on joints -->
    <provideFeedback>true</provideFeedback>
  </gazebo>
  <transmission name="fr3_joint4_transmission">
    <type>transmission_interface/SimpleTransmission</type>
    <joint name="fr3_joint4">
      <hardwareInterface>hardware_interface/VelocityJointInterface</hardwareInterface>
    </joint>
    <actuator name="fr3_joint4_motor">
      <hardwareInterface>hardware_interface/VelocityJointInterface</hardwareInterface>
    </actuator>
  </transmission>
  <gazebo reference="fr3_joint5">
    <!-- Needed for ODE to output external wrenches on joints -->
    <provideFeedback>true</provideFeedback>
  </gazebo>
  <transmission name="fr3_joint5_transmission">
    <type>transmission_interface/SimpleTransmission</type>
    <joint name="fr3_joint5">
      <hardwareInterface>hardware_interface/VelocityJointInterface</hardwareInterface>
    </joint>
    <actuator name="fr3_joint5_motor">
      <hardwareInterface>hardware_interface/VelocityJointInterface</hardwareInterface>
    </actuator>
  </transmission>
  <gazebo reference="fr3_joint6">
    <!-- Needed for ODE to output external wrenches on joints -->
    <provideFeedback>true</provideFeedback>
  </gazebo>
  <transmission name="fr3_joint6_transmission">
    <type>transmission_interface/SimpleTransmission</type>
    <joint name="fr3_joint6">
      <hardwareInterface>hardware_interface/VelocityJointInterface</hardwareInterface>
    </joint>
    <actuator name="fr3_joint6_motor">
      <hardwareInterface>hardware_interface/VelocityJointInterface</hardwareInterface>
    </actuator>
  </transmission>
  <gazebo reference="fr3_joint7">
    <!-- Needed for ODE to output external wrenches on joints -->
    <provideFeedback>true</provideFeedback>
  </gazebo>
  <transmission name="fr3_joint7_transmission">
    <type>transmission_interface/SimpleTransmission</type>
    <joint name="fr3_joint7">
      <hardwareInterface>hardware_interface/VelocityJointInterface</hardwareInterface>
    </joint>
    <actuator name="fr3_joint7_motor">
      <hardwareInterface>hardware_interface/VelocityJointInterface</hardwareInterface>
    </actuator>
  </transmission>
  <gazebo reference="fr3_joint1">
    <!-- Needed for ODE to output external wrenches on joints -->
    <provideFeedback>true</provideFeedback>
  </gazebo>
  <transmission name="fr3_joint1_transmission">
    <type>transmission_interface/SimpleTransmission</type>
    <joint name="fr3_joint1">
      <hardwareInterface>hardware_interface/EffortJointInterface</hardwareInterface>
    </joint>
    <actuator name="fr3_joint1_motor">
      <hardwareInterface>hardware_interface/EffortJointInterface</hardwareInterface>
    </actuator>
  </transmission>
  <gazebo reference="fr3_joint2">
    <!-- Needed for ODE to output external wrenches on joints -->
    <provideFeedback>true</provideFeedback>
  </gazebo>
  <transmission name="fr3_joint2_transmission">
    <type>transmission_interface/SimpleTransmission</type>
    <joint name="fr3_joint2">
      <hardwareInterface>hardware_interface/EffortJointInterface</hardwareInterface>
    </joint>
    <actuator name="fr3_joint2_motor">
      <hardwareInterface>hardware_interface/EffortJointInterface</hardwareInterface>
    </actuator>
  </transmission>
  <gazebo reference="fr3_joint3">
    <!-- Needed for ODE to output external wrenches on joints -->
    <provideFeedback>true</provideFeedback>
  </gazebo>
  <transmission name="fr3_joint3_transmission">
    <type>transmission_interface/SimpleTransmission</type>
    <joint name="fr3_joint3">
      <hardwareInterface>hardware_interface/EffortJointInterface</hardwareInterface>
    </joint>
    <actuator name="fr3_joint3_motor">
      <hardwareInterface>hardware_interface/EffortJointInterface</hardwareInterface>
    </actuator>
  </transmission>
  <gazebo reference="fr3_joint4">
    <!-- Needed for ODE to output external wrenches on joints -->
    <provideFeedback>true</provideFeedback>
  </gazebo>
  <transmission name="fr3_joint4_transmission">
    <type>transmission_interface/SimpleTransmission</type>
    <joint name="fr3_joint4">
      <hardwareInterface>hardware_interface/EffortJointInterface</hardwareInterface>
    </joint>
    <actuator name="fr3_joint4_motor">
      <hardwareInterface>hardware_interface/EffortJointInterface</hardwareInterface>
    </actuator>
  </transmission>
  <gazebo reference="fr3_joint5">
    <!-- Needed for ODE to output external wrenches on joints -->
    <provideFeedback>true</provideFeedback>
  </gazebo>
  <transmission name="fr3_joint5_transmission">
    <type>transmission_interface/SimpleTransmission</type>
    <joint name="fr3_joint5">
      <hardwareInterface>hardware_interface/EffortJointInterface</hardwareInterface>
    </joint>
    <actuator name="fr3_joint5_motor">
      <hardwareInterface>hardware_interface/EffortJointInterface</hardwareInterface>
    </actuator>
  </transmission>
  <gazebo reference="fr3_joint6">
    <!-- Needed for ODE to output external wrenches on joints -->
    <provideFeedback>true</provideFeedback>
  </gazebo>
  <transmission name="fr3_joint6_transmission">
    <type>transmission_interface/SimpleTransmission</type>
    <joint name="fr3_joint6">
      <hardwareInterface>hardware_interface/EffortJointInterface</hardwareInterface>
    </joint>
    <actuator name="fr3_joint6_motor">
      <hardwareInterface>hardware_interface/EffortJointInterface</hardwareInterface>
    </actuator>
  </transmission>
  <gazebo reference="fr3_joint7">
    <!-- Needed for ODE to output external wrenches on joints -->
    <provideFeedback>true</provideFeedback>
  </gazebo>
  <transmission name="fr3_joint7_transmission">
    <type>transmission_interface/SimpleTransmission</type>
    <joint name="fr3_joint7">
      <hardwareInterface>hardware_interface/EffortJointInterface</hardwareInterface>
    </joint>
    <actuator name="fr3_joint7_motor">
      <hardwareInterface>hardware_interface/EffortJointInterface</hardwareInterface>
    </actuator>
  </transmission>
  <transmission name="fr3_franka_state">
    <type>franka_hw/FrankaStateInterface</type>
    <joint name="fr3_joint1">
      <hardwareInterface>franka_hw/FrankaStateInterface</hardwareInterface>
    </joint>
    <joint name="fr3_joint2">
      <hardwareInterface>franka_hw/FrankaStateInterface</hardwareInterface>
    </joint>
    <joint name="fr3_joint3">
      <hardwareInterface>franka_hw/FrankaStateInterface</hardwareInterface>
    </joint>
    <joint name="fr3_joint4">
      <hardwareInterface>franka_hw/FrankaStateInterface</hardwareInterface>
    </joint>
    <joint name="fr3_joint5">
      <hardwareInterface>franka_hw/FrankaStateInterface</hardwareInterface>
    </joint>
    <joint name="fr3_joint6">
      <hardwareInterface>franka_hw/FrankaStateInterface</hardwareInterface>
    </joint>
    <joint name="fr3_joint7">
      <hardwareInterface>franka_hw/FrankaStateInterface</hardwareInterface>
    </joint>
    <actuator name="fr3_motor1">
      <hardwareInterface>franka_hw/FrankaStateInterface</hardwareInterface>
    </actuator>
    <actuator name="fr3_motor2">
      <hardwareInterface>franka_hw/FrankaStateInterface</hardwareInterface>
    </actuator>
    <actuator name="fr3_motor3">
      <hardwareInterface>franka_hw/FrankaStateInterface</hardwareInterface>
    </actuator>
    <actuator name="fr3_motor4">
      <hardwareInterface>franka_hw/FrankaStateInterface</hardwareInterface>
    </actuator>
    <actuator name="fr3_motor5">
      <hardwareInterface>franka_hw/FrankaStateInterface</hardwareInterface>
    </actuator>
    <actuator name="fr3_motor6">
      <hardwareInterface>franka_hw/FrankaStateInterface</hardwareInterface>
    </actuator>
    <actuator name="fr3_motor7">
      <hardwareInterface>franka_hw/FrankaStateInterface</hardwareInterface>
    </actuator>
  </transmission>
  <transmission name="fr3_franka_model">
    <type>franka_hw/FrankaModelInterface</type>
    <joint name="fr3_joint1">
      <role>root</role>
      <hardwareInterface>franka_hw/FrankaModelInterface</hardwareInterface>
    </joint>
    <joint name="fr3_joint8">
      <role>tip</role>
      <hardwareInterface>franka_hw/FrankaModelInterface</hardwareInterface>
    </joint>
    <actuator name="fr3_joint1_motor_root">
      <hardwareInterface>franka_hw/FrankaModelInterface</hardwareInterface>
    </actuator>
    <actuator name="fr3_joint8_motor_tip">
      <hardwareInterface>franka_hw/FrankaModelInterface</hardwareInterface>
    </actuator>
  </transmission>
  <gazebo reference="fr3_finger_joint1">
    <!-- Needed for ODE to output external wrenches on joints -->
    <provideFeedback>true</provideFeedback>
  </gazebo>
  <transmission name="fr3_finger_joint1_transmission">
    <type>transmission_interface/SimpleTransmission</type>
    <joint name="fr3_finger_joint1">
      <hardwareInterface>hardware_interface/EffortJointInterface</hardwareInterface>
    </joint>
    <actuator name="fr3_finger_joint1_motor">
      <hardwareInterface>hardware_interface/EffortJointInterface</hardwareInterface>
    </actuator>
  </transmission>
  <gazebo reference="fr3_finger_joint2">
    <!-- Needed for ODE to output external wrenches on joints -->
    <provideFeedback>true</provideFeedback>
  </gazebo>
  <transmission name="fr3_finger_joint2_transmission">
    <type>transmission_interface/SimpleTransmission</type>
    <joint name="fr3_finger_joint2">
      <hardwareInterface>hardware_interface/EffortJointInterface</hardwareInterface>
    </joint>
    <actuator name="fr3_finger_joint2_motor">
      <hardwareInterface>hardware_interface/EffortJointInterface</hardwareInterface>
    </actuator>
  </transmission>
  <gazebo reference="fr3_leftfinger">
    <collision>
      <max_contacts>10</max_contacts>
      <surface>
        <contact>
          <ode>
            <!-- These two parameter need application specific tuning. -->
            <!-- Usually you want no "snap out" velocity and a generous -->
            <!-- penetration depth to keep the grasping stable -->
            <max_vel>0</max_vel>
            <min_depth>0.001</min_depth>
          </ode>
        </contact>
        <friction>
          <ode>
            <mu>1.13</mu>
            <mu2>1.13</mu2>
          </ode>
        </friction>
        <bounce/>
      </surface>
    </collision>
  </gazebo>
  <gazebo reference="fr3_rightfinger">
    <collision>
      <max_contacts>10</max_contacts>
      <surface>
        <contact>
          <ode>
            <!-- These two parameter need application specific tuning. -->
            <!-- Usually you want no "snap out" velocity and a generous -->
            <!-- penetration depth to keep the grasping stable -->
            <max_vel>0</max_vel>
            <min_depth>0.001</min_depth>
          </ode>
        </contact>
        <friction>
          <ode>
            <mu>1.13</mu>
            <mu2>1.13</mu2>
          </ode>
        </friction>
        <bounce/>
      </surface>
    </collision>
  </gazebo>
  <!-- Local ros2_control block so Gazebo spawns the FR3 already looking at the
       right-side plant instead of starting folded downward and sweeping through
       front tomatoes. Keep this in this workspace instead of patching the
       upstream franka_description xacro. -->
  <ros2_control name="FrankaHardwareInterface" type="system">
    <hardware>
      <param name="version">1.0.0</param>
      <param name="robot_type">fr3</param>
      <param name="prefix"/>
      <plugin>gz_ros2_control/GazeboSimSystem</plugin>
    </hardware>
    <joint name="fr3_joint1">
      <command_interface name="position"/>
      <command_interface name="velocity"/>
      <state_interface name="position">
        <param name="initial_value">-1.71</param>
      </state_interface>
      <state_interface name="velocity"/>
      <state_interface name="effort"/>
    </joint>
    <joint name="fr3_joint2">
      <command_interface name="position"/>
      <command_interface name="velocity"/>
      <state_interface name="position">
        <param name="initial_value">-1.267</param>
      </state_interface>
      <state_interface name="velocity"/>
      <state_interface name="effort"/>
    </joint>
    <joint name="fr3_joint3">
      <command_interface name="position"/>
      <command_interface name="velocity"/>
      <state_interface name="position">
        <param name="initial_value">0.0</param>
      </state_interface>
      <state_interface name="velocity"/>
      <state_interface name="effort"/>
    </joint>
    <joint name="fr3_joint4">
      <command_interface name="position"/>
      <command_interface name="velocity"/>
      <state_interface name="position">
        <param name="initial_value">-2.792</param>
      </state_interface>
      <state_interface name="velocity"/>
      <state_interface name="effort"/>
    </joint>
    <joint name="fr3_joint5">
      <command_interface name="position"/>
      <command_interface name="velocity"/>
      <state_interface name="position">
        <param name="initial_value">0.0</param>
      </state_interface>
      <state_interface name="velocity"/>
      <state_interface name="effort"/>
    </joint>
    <joint name="fr3_joint6">
      <command_interface name="position"/>
      <command_interface name="velocity"/>
      <state_interface name="position">
        <param name="initial_value">2.8</param>
      </state_interface>
      <state_interface name="velocity"/>
      <state_interface name="effort"/>
    </joint>
    <joint name="fr3_joint7">
      <command_interface name="position"/>
      <command_interface name="velocity"/>
      <state_interface name="position">
        <param name="initial_value">0.0</param>
      </state_interface>
      <state_interface name="velocity"/>
      <state_interface name="effort"/>
    </joint>
    <joint name="fr3_finger_joint1">
      <command_interface name="position"/>
      <state_interface name="position">
        <param name="initial_value">0.04</param>
      </state_interface>
      <state_interface name="velocity"/>
      <state_interface name="effort"/>
    </joint>
    <joint name="fr3_finger_joint2">
      <command_interface name="position"/>
      <state_interface name="position">
        <param name="initial_value">0.04</param>
      </state_interface>
      <state_interface name="velocity"/>
      <state_interface name="effort"/>
    </joint>
    <gpio name="vx">
      <command_interface name="cartesian_velocity"/>
      <param name="index">0</param>
    </gpio>
    <gpio name="vy">
      <command_interface name="cartesian_velocity"/>
      <param name="index">1</param>
    </gpio>
    <gpio name="vz">
      <command_interface name="cartesian_velocity"/>
      <param name="index">2</param>
    </gpio>
    <gpio name="wx">
      <command_interface name="cartesian_velocity"/>
      <param name="index">3</param>
    </gpio>
    <gpio name="wy">
      <command_interface name="cartesian_velocity"/>
      <param name="index">4</param>
    </gpio>
    <gpio name="wz">
      <command_interface name="cartesian_velocity"/>
      <param name="index">5</param>
    </gpio>
    <gpio name="0">
      <command_interface name="cartesian_pose_command"/>
      <param name="index">0</param>
    </gpio>
    <gpio name="1">
      <command_interface name="cartesian_pose_command"/>
      <param name="index">1</param>
    </gpio>
    <gpio name="2">
      <command_interface name="cartesian_pose_command"/>
      <param name="index">2</param>
    </gpio>
    <gpio name="3">
      <command_interface name="cartesian_pose_command"/>
      <param name="index">3</param>
    </gpio>
    <gpio name="4">
      <command_interface name="cartesian_pose_command"/>
      <param name="index">4</param>
    </gpio>
    <gpio name="5">
      <command_interface name="cartesian_pose_command"/>
      <param name="index">5</param>
    </gpio>
    <gpio name="6">
      <command_interface name="cartesian_pose_command"/>
      <param name="index">6</param>
    </gpio>
    <gpio name="7">
      <command_interface name="cartesian_pose_command"/>
      <param name="index">7</param>
    </gpio>
    <gpio name="8">
      <command_interface name="cartesian_pose_command"/>
      <param name="index">8</param>
    </gpio>
    <gpio name="9">
      <command_interface name="cartesian_pose_command"/>
      <param name="index">9</param>
    </gpio>
    <gpio name="10">
      <command_interface name="cartesian_pose_command"/>
      <param name="index">10</param>
    </gpio>
    <gpio name="11">
      <command_interface name="cartesian_pose_command"/>
      <param name="index">11</param>
    </gpio>
    <gpio name="12">
      <command_interface name="cartesian_pose_command"/>
      <param name="index">12</param>
    </gpio>
    <gpio name="13">
      <command_interface name="cartesian_pose_command"/>
      <param name="index">13</param>
    </gpio>
    <gpio name="14">
      <command_interface name="cartesian_pose_command"/>
      <param name="index">14</param>
    </gpio>
    <gpio name="15">
      <command_interface name="cartesian_pose_command"/>
      <param name="index">15</param>
    </gpio>
    <gpio name="joint_3_position">
      <command_interface name="elbow_command"/>
      <param name="index">0</param>
    </gpio>
    <gpio name="joint_4_sign">
      <command_interface name="elbow_command"/>
      <param name="index">1</param>
    </gpio>
  </ros2_control>
  <!-- Attach fr3_link0 to Panther mount_link -->
  <joint name="panther_to_franka_joint" type="fixed">
    <parent link="mount_link"/>
    <child link="fr3_link0"/>
    <origin rpy="0 0 0" xyz="0.0 0.0 0.0"/>
  </joint>
  <link name="fr3_camera_link">
    <visual>
      <origin rpy="1.5707963267948966 0 1.5707963267948966" xyz="0 0 0"/>
      <geometry>
        <mesh filename="package://realsense2_description/meshes/d435.dae"/>
      </geometry>
    </visual>
    <collision>
      <origin rpy="0 0 0" xyz="0 0 0"/>
      <geometry>
        <box size="0.025 0.090 0.025"/>
      </geometry>
    </collision>
    <inertial>
      <mass value="0.072"/>
      <inertia ixx="3.881e-3" ixy="0" ixz="0" iyy="4.989e-4" iyz="0" izz="3.879e-3"/>
    </inertial>
  </link>
  <joint name="fr3_camera_joint" type="fixed">
    <parent link="fr3_hand"/>
    <child link="fr3_camera_link"/>
    <!--
        xyz="0.10 0 0.08":
          +0.10m in TCP X = 10cm outward to the side (clears the ~8cm wrist body)
          +0.08m in TCP Z = 8cm toward wrist (TCP +Z points toward wrist, not fingertips)
        rpy="0 0 0": camera looks along TCP forward axis (link7 direction).
        If camera appears on the wrong side, flip X to -0.10 or swap to Y axis.
      -->
    <origin rpy="3.141592653589793 -1.5707963267948966 0" xyz="0.04 0 0.06"/>
  </joint>
  <!-- ROS optical frames (standard REP-103 convention) -->
  <link name="fr3_camera_color_optical_frame"/>
  <joint name="fr3_camera_color_optical_joint" type="fixed">
    <parent link="fr3_camera_link"/>
    <child link="fr3_camera_color_optical_frame"/>
    <origin rpy="-1.5707963267948966 0 -1.5707963267948966" xyz="0 0 0"/>
  </joint>
  <link name="fr3_camera_depth_optical_frame"/>
  <joint name="fr3_camera_depth_optical_joint" type="fixed">
    <parent link="fr3_camera_link"/>
    <child link="fr3_camera_depth_optical_frame"/>
    <origin rpy="-1.5707963267948966 0 -1.5707963267948966" xyz="0 0 0"/>
  </joint>
  <!-- Gazebo sensors: one color + one depth stream. -->
  <gazebo reference="fr3_camera_link">
    <sensor name="fr3_d435_color" type="camera">
      <always_on>1</always_on>
      <update_rate>30</update_rate>
      <visualize>false</visualize>
      <topic>/camera/color/image_raw</topic>
      <camera name="fr3_d435_color_cam">
        <horizontal_fov>1.211</horizontal_fov>
        <image>
          <width>640</width>
          <height>480</height>
          <format>RGB_INT8</format>
        </image>
        <clip>
          <near>0.05</near>
          <far>10</far>
        </clip>
      </camera>
    </sensor>
    <sensor name="fr3_d435_depth" type="depth_camera">
      <always_on>1</always_on>
      <update_rate>30</update_rate>
      <visualize>false</visualize>
      <topic>/camera/depth/image</topic>
      <camera name="fr3_d435_depth_cam">
        <horizontal_fov>1.211</horizontal_fov>
        <image>
          <width>640</width>
          <height>480</height>
        </image>
        <clip>
          <near>0.05</near>
          <far>10</far>
        </clip>
      </camera>
    </sensor>
  </gazebo>
  <material name="soft_gripper_pad">
    <color rgba="0.08 0.08 0.08 1.0"/>
  </material>
  <link name="fr3_leftfinger_tomato_pad">
    <visual name="fr3_leftfinger_tomato_pad_visual">
      <geometry>
        <box size="0.045 0.012 0.030"/>
      </geometry>
      <material name="soft_gripper_pad"/>
    </visual>
    <collision name="fr3_leftfinger_tomato_pad_collision">
      <geometry>
        <box size="0.045 0.012 0.030"/>
      </geometry>
    </collision>
    <inertial>
      <mass value="0.015"/>
      <origin rpy="0 0 0" xyz="0 0 0"/>
      <inertia ixx="1.305e-6" ixy="0" ixz="0" iyy="3.656e-6" iyz="0" izz="2.711e-6"/>
    </inertial>
  </link>
  <joint name="fr3_leftfinger_tomato_pad_joint" type="fixed">
    <parent link="fr3_leftfinger"/>
    <child link="fr3_leftfinger_tomato_pad"/>
    <origin rpy="0 0 0" xyz="0 0.00758 0.04525"/>
  </joint>
  <link name="fr3_rightfinger_tomato_pad">
    <visual name="fr3_rightfinger_tomato_pad_visual">
      <geometry>
        <box size="0.045 0.012 0.030"/>
      </geometry>
      <material name="soft_gripper_pad"/>
    </visual>
    <collision name="fr3_rightfinger_tomato_pad_collision">
      <geometry>
        <box size="0.045 0.012 0.030"/>
      </geometry>
    </collision>
    <inertial>
      <mass value="0.015"/>
      <origin rpy="0 0 0" xyz="0 0 0"/>
      <inertia ixx="1.305e-6" ixy="0" ixz="0" iyy="3.656e-6" iyz="0" izz="2.711e-6"/>
    </inertial>
  </link>
  <joint name="fr3_rightfinger_tomato_pad_joint" type="fixed">
    <parent link="fr3_rightfinger"/>
    <child link="fr3_rightfinger_tomato_pad"/>
    <origin rpy="0 0 0" xyz="0 0.00758 0.04525"/>
  </joint>
  <gazebo reference="fr3_leftfinger_tomato_pad">
    <mu1>1000</mu1>
    <mu2>1000</mu2>
    <kp>1000000.0</kp>
    <kd>100.0</kd>
    <minDepth>0.002</minDepth>
    <maxVel>0</maxVel>
  </gazebo>
  <gazebo reference="fr3_rightfinger_tomato_pad">
    <mu1>1000</mu1>
    <mu2>1000</mu2>
    <kp>1000000.0</kp>
    <kd>100.0</kd>
    <minDepth>0.002</minDepth>
    <maxVel>0</maxVel>
  </gazebo>
  <gazebo reference="fr3_leftfinger">
    <mu1>1000</mu1>
    <mu2>1000</mu2>
    <kp>1000000.0</kp>
    <kd>100.0</kd>
    <minDepth>0.002</minDepth>
    <maxVel>0</maxVel>
  </gazebo>
  <gazebo reference="fr3_rightfinger">
    <mu1>1000</mu1>
    <mu2>1000</mu2>
    <kp>1000000.0</kp>
    <kd>100.0</kd>
    <minDepth>0.002</minDepth>
    <maxVel>0</maxVel>
  </gazebo>
  <!-- Lidar: uses Husarion's built-in LDR06 from components.yaml -->
</robot>
